Workbook

Sheet 4P 3PH rating 
A1: Dingol Generator Rating Table (4-pole 3-phase rating)
A2: Model | B2: Three Phase 50Hz 1500RPM | J2: Three Phase 60Hz 1800RPM
A3: Power Factor | B3: 0.8 | D3: 0.8 | F3: 0.8 | H3: 0.8 | J3: 0.8 | L3: 0.8 | N3: 0.8 | P3: 0.8 | R3: 0.8 | T3: 0.8
A4: Volts
A5: Star(W12&W13) | B5: 380 | D5: 400 | F5: 415 | H5: 440 | J5: 380-416 | N5: 416 | P5: 440 | R5: 460 | T5: 480
A6: Delta(W12&W13) | B6: 220 | D6: 230 | F6: 240 | H6: 254 | J6: 220-240 | N6: 240 | P6: 254 | R6: 266 | T6: 277
A7: Series Star(W11&W14) | B7: 380 | D7: 400 | F7: 415 | H7: 440 | J7: - | L7: 380-416 | N7: 416 | P7: 440 | R7: 460 | T7: 480
A8: Parallel Star(W11&W14) | B8: 190 | D8: 200 | F8: 208 | H8: 220 | J8: - | L8: 190-208 | N8: 208 | P8: 220 | R8: 230 | T8: 240
A9: Series Delta | B9: 220 | D9: 230 | F9: 240 | H9: 254 | J9: - | L9: 220-240 | N9: 240 | P9: 254 | R9: 266 | T9: 277
A10: Parallel delta | B10: =B9/2 -> 110 | D10: =D9/2 -> 115 | F10: =F9/2 -> 120 | H10: =H9/2 -> 127 | L10: 110-120 | N10: =N9/2 -> 120 | P10: =P9/2 -> 127 | R10: =R9/2 -> 133 | T10: =T9/2 -> 138.5
A11: Winding No. | B11: 11 | D11: 11 | F11: 11 | H11: 11 | J11: 13 | L11: 14 | N11: 11 | P11: 11 | R11: 11 | T11: 11
A12: Rating | B12: KVA | C12: KW | D12: KVA | E12: KW | F12: KVA | G12: KW | H12: KVA | I12: KW | J12: KVA | K12: KW | L12: KVA | M12: KW | N12: KVA | O12: KW | P12: KVA | Q12: KW | R12: KVA | S12: KW | T12: KVA | U12: KW
A13: DG164A | B13: 8.1 | C13: 6.5 | D13: 8.1 | E13: 6.5 | F13: 8.1 | G13: 6.5 | H13: 6.2 | I13: =H13*0.8 -> 4.96 | J13: - | K13: - | L13: 9.6 | M13: 7.7 | N13: 9.6 | O13: 7.7 | P13: 10.2 | Q13: 8.2 | R13: 10.2 | S13: 8.2 | T13: 10.2 | U13: 8.2
A14: DG164B | B14: 11 | C14: =B14*0.8 -> 8.8 | D14: 11 | E14: =D14*0.8 -> 8.8 | F14: 11 | G14: =F14*0.8 -> 8.8 | H14: 8.4 | I14: =H14*0.8 -> 6.72 | J14: - | K14: - | L14: 13 | M14: 10.4 | N14: 13 | O14: 10.4 | P14: 13.8 | Q14: 11 | R14: 13.8 | S14: 11 | T14: 13.8 | U14: 11
A15: DG164C | B15: 13.5 | C15: =B15*0.8 -> 10.8 | D15: 13.5 | E15: =D15*0.8 -> 10.8 | F15: 13.5 | G15: =F15*0.8 -> 10.8 | H15: 11 | I15: =H15*0.8 -> 8.8 | J15: - | K15: - | L15: 16 | M15: 12.8 | N15: 16 | O15: 12.8 | P15: 16.9 | Q15: 13.5 | R15: 16.9 | S15: 13.5 | T15: 16.9 | U15: 13.5
A16: DG164D | B16: 16 | C16: =B16*0.8 -> 12.8 | D16: 16 | E16: =D16*0.8 -> 12.8 | F16: 16 | G16: =F16*0.8 -> 12.8 | H16: 13.5 | I16: =H16*0.8 -> 10.8 | J16: - | K16: - | L16: 20 | M16: 16 | N16: 18.9 | O16: 15.1 | P16: 20 | Q16: 16 | R16: 20 | S16: 16 | T16: 20 | U16: 16
A18: DG184ES | B18: 20 | C18: =B18*0.8 -> 16 | D18: 20 | E18: =D18*0.8 -> 16 | F18: 20 | G18: =F18*0.8 -> 16 | H18: 15 | I18: =H18*0.8 -> 12 | J18: - | K18: - | L18: 25 | M18: 20 | N18: 24 | O18: =N18*0.8 -> 19.2 | P18: 25 | Q18: =P18*0.8 -> 20 | R18: 25 | S18: =R18*0.8 -> 20 | T18: 25 | U18: =T18*0.8 -> 20
A19: DG184E | B19: 22.5 | C19: =B19*0.8 -> 18 | D19: 22.5 | E19: =D19*0.8 -> 18 | F19: 22.5 | G19: =F19*0.8 -> 18 | H19: 17.5 | I19: =H19*0.8 -> 14 | J19: - | K19: - | L19: 27.5 | M19: 22 | N19: 27.5 | O19: 22 | P19: 28.8 | Q19: 23 | R19: 28.8 | S19: 23 | T19: 30 | U19: 24
A20: DG184F | B20: 27.5 | C20: =B20*0.8 -> 22 | D20: 27.5 | E20: =D20*0.8 -> 22 | F20: 27.5 | G20: =F20*0.8 -> 22 | H20: 22 | I20: =H20*0.8 -> 17.6 | J20: - | K20: - | L20: 32.5 | M20: 26 | N20: 32.5 | O20: 26 | P20: 34.4 | Q20: 27.5 | R20: 34.4 | S20: 27.5 | T20: 35 | U20: 28
A21: DG184G | B21: 31.3 | C21: 25 | D21: 31.3 | E21: 25 | F21: 31.3 | G21: 25 | H21: 25 | I21: =H21*0.8 -> 20 | J21: - | K21: - | L21: 37.5 | M21: 30 | N21: 35 | O21: =N21*0.8 -> 28 | P21: 37.5 | Q21: =P21*0.8 -> 30 | R21: 37.5 | S21: =R21*0.8 -> 30 | T21: 37.5 | U21: =T21*0.8 -> 30
A22: DG184H | B22: 37.5 | C22: =B22*0.8 -> 30 | D22: 37.5 | E22: =D22*0.8 -> 30 | F22: 37.5 | G22: =F22*0.8 -> 30 | H22: 30 | I22: =H22*0.8 -> 24 | J22: - | K22: - | L22: 43.5 | M22: 34.8 | N22: 44.3 | O22: 35.4 | P22: 46.9 | Q22: 37.5 | R22: 46.9 | S22: 37.5 | T22: 46.9 | U22: 37.5
A23: DG184J | B23: 40 | C23: =B23*0.8 -> 32 | D23: 40 | E23: =D23*0.8 -> 32 | F23: 40 | G23: =F23*0.8 -> 32 | H23: 32 | I23: =H23*0.8 -> 25.6 | J23: - | K23: - | L23: 47.5 | M23: 38 | N23: 47.3 | O23: =N23*0.8 -> 37.84 | P23: 50 | Q23: =P23*0.8 -> 40 | R23: 50 | S23: =R23*0.8 -> 40 | T23: 50 | U23: =T23*0.8 -> 40
A25: DG224C | B25: 42.5 | C25: =B25*0.8 -> 34 | D25: 42.5 | E25: =D25*0.8 -> 34 | F25: 42.5 | G25: =F25*0.8 -> 34 | H25: 30 | I25: =H25*0.8 -> 24 | J25: - | K25: - | L25: 55 | M25: 44 | N25: 50 | O25: =N25*0.8 -> 40 | P25: 52.5 | Q25: =P25*0.8 -> 42 | R25: 52.5 | S25: =R25*0.8 -> 42 | T25: 55 | U25: =T25*0.8 -> 44
A26: DG224D | B26: 50 | C26: =B26*0.8 -> 40 | D26: 50 | E26: =D26*0.8 -> 40 | F26: 50 | G26: =F26*0.8 -> 40 | H26: 37.5 | I26: =H26*0.8 -> 30 | J26: - | K26: - | L26: 62.5 | M26: 50 | N26: 60 | O26: =N26*0.8 -> 48 | P26: 62.5 | Q26: =P26*0.8 -> 50 | R26: 62.5 | S26: =R26*0.8 -> 50 | T26: 65 | U26: =T26*0.8 -> 52
A27: DG224E | B27: 60 | C27: =B27*0.8 -> 48 | D27: 60 | E27: =D27*0.8 -> 48 | F27: 60 | G27: =F27*0.8 -> 48 | H27: 45 | I27: =H27*0.8 -> 36 | J27: - | K27: - | L27: 70 | M27: 56 | N27: 67.5 | O27: =N27*0.8 -> 54 | P27: 70 | Q27: =P27*0.8 -> 56 | R27: 70 | S27: =R27*0.8 -> 56 | T27: 75 | U27: =T27*0.8 -> 60
A28: DG224F | B28: 72.5 | C28: =B28*0.8 -> 58 | D28: 72.5 | E28: =D28*0.8 -> 58 | F28: 72.5 | G28: =F28*0.8 -> 58 | H28: 55 | I28: =H28*0.8 -> 44 | J28: - | K28: - | L28: 85 | M28: 68 | N28: 83.8 | O28: 67 | P28: 87.5 | Q28: =P28*0.8 -> 70 | R28: 87.5 | S28: =R28*0.8 -> 70 | T28: 93.8 | U28: =T28*0.8 -> 75.04
A29: DG224G | B29: 85 | C29: =B29*0.8 -> 68 | D29: 85 | E29: =D29*0.8 -> 68 | F29: 85 | G29: =F29*0.8 -> 68 | H29: 75 | I29: =H29*0.8 -> 60 | J29: - | K29: - | L29: 100 | M29: 80 | N29: 93.8 | O29: 75 | P29: 97.5 | Q29: =P29*0.8 -> 78 | R29: 100 | S29: =R29*0.8 -> 80 | T29: 103.8 | U29: =T29*0.8 -> 83.04
A31: DG274C | B31: 100 | C31: =B31*0.8 -> 80 | D31: 100 | E31: =D31*0.8 -> 80 | F31: 100 | G31: =F31*0.8 -> 80 | H31: - | I31: - | J31: - | K31: - | L31: 120 | M31: 96 | N31: 112.5 | O31: =N31*0.8 -> 90 | P31: 117.5 | Q31: =P31*0.8 -> 94 | R31: 117.5 | S31: =R31*0.8 -> 94 | T31: 125 | U31: =T31*0.8 -> 100
A32: DG274D | B32: 125 | C32: =B32*0.8 -> 100 | D32: 125 | E32: =D32*0.8 -> 100 | F32: 125 | G32: =F32*0.8 -> 100 | H32: - | I32: - | J32: - | K32: - | L32: 140 | M32: =L32*0.8 -> 112 | N32: 140 | O32: =N32*0.8 -> 112 | P32: 150 | Q32: =P32*0.8 -> 120 | R32: 150 | S32: =R32*0.8 -> 120 | T32: 150 | U32: =T32*0.8 -> 120
A33: DG274E | B33: 140 | C33: =B33*0.8 -> 112 | D33: 140 | E33: =D33*0.8 -> 112 | F33: 140 | G33: =F33*0.8 -> 112 | H33: - | I33: - | J33: - | K33: - | L33: 160 | M33: 128 | N33: 160 | O33: =N33*0.8 -> 128 | P33: 168 | Q33: 134 | R33: 168 | S33: 134 | T33: 178 | U33: =T33*0.8 -> 142.4
A34: DG274EL | B34: 150 | C34: =B34*0.8 -> 120 | D34: 150 | E34: =D34*0.8 -> 120 | F34: 150 | G34: =F34*0.8 -> 120 | H34: - | I34: - | J34: - | K34: - | L34: 170 | M34: =L34*0.8 -> 136 | N34: 170 | O34: =N34*0.8 -> 136 | P34: 180 | Q34: 144 | R34: 180 | S34: 144 | T34: 190 | U34: =T34*0.8 -> 152
A35: DG274F | B35: 160 | C35: =B35*0.8 -> 128 | D35: 160 | E35: =D35*0.8 -> 128 | F35: 160 | G35: =F35*0.8 -> 128 | H35: - | I35: - | J35: - | K35: - | L35: 180 | M35: 144 | N35: 181 | O35: =N35*0.8 -> 144.8 | P35: 190 | Q35: =P35*0.8 -> 152 | R35: 190 | S35: =R35*0.8 -> 152 | T35: 200 | U35: =T35*0.8 -> 160
A36: DG274G | B36: 180 | C36: =B36*0.8 -> 144 | D36: 180 | E36: =D36*0.8 -> 144 | F36: 180 | G36: =F36*0.8 -> 144 | H36: - | I36: - | J36: - | K36: - | L36: 200 | M36: 160 | N36: 200 | O36: =N36*0.8 -> 160 | P36: 213 | Q36: =P36*0.8 -> 170.4 | R36: 213 | S36: =R36*0.8 -> 170.4 | T36: 220 | U36: =T36*0.8 -> 176
A37: DG274H | B37: 200 | C37: =B37*0.8 -> 160 | D37: 200 | E37: =D37*0.8 -> 160 | F37: 200 | G37: =F37*0.8 -> 160 | H37: - | I37: - | J37: - | K37: - | L37: 237.5 | M37: 190 | N37: 237 | O37: =N37*0.8 -> 189.6 | P37: 245 | Q37: =P37*0.8 -> 196 | R37: 245 | S37: =R37*0.8 -> 196 | T37: 250 | U37: =T37*0.8 -> 200
A38: DG274J | B38: 225 | C38: =B38*0.8 -> 180 | D38: 225 | E38: =D38*0.8 -> 180 | F38: 225 | G38: =F38*0.8 -> 180 | H38: - | I38: - | J38: - | K38: - | L38: 280 | M38: 225 | N38: 269 | O38: =N38*0.8 -> 215.2 | P38: 281 | Q38: 225 | R38: 281 | S38: =R38*0.8 -> 224.8 | T38: 300 | U38: =T38*0.8 -> 240
A39: DG274K | B39: 250 | C39: =B39*0.8 -> 200 | D39: 250 | E39: =D39*0.8 -> 200 | F39: 250 | G39: =F39*0.8 -> 200 | H39: - | I39: - | J39: - | K39: - | L39: 300 | M39: 240 | N39: 291 | O39: =N39*0.8 -> 232.8 | P39: 300 | Q39: 240 | R39: 300 | S39: 240 | T39: 312.5 | U39: =T39*0.8 -> 250
A41: DG444C | B41: 250 | C41: =B41*0.8 -> 200 | D41: 250 | E41: =D41*0.8 -> 200 | F41: 250 | G41: =F41*0.8 -> 200 | H41: 250 | I41: =H41*0.8 -> 200 | J41: 300 | K41: 240 | L41: 300 | M41: 240 | N41: 287.5 | O41: =N41*0.8 -> 230 | P41: 300 | Q41: 240 | R41: 300 | S41: 240 | T41: 312.5 | U41: =T41*0.8 -> 250
A42: DG444D | B42: 300 | C42: =B42*0.8 -> 240 | D42: 300 | E42: =D42*0.8 -> 240 | F42: 300 | G42: =F42*0.8 -> 240 | H42: 280 | I42: =H42*0.8 -> 224 | J42: 350 | K42: 280 | L42: 350 | M42: 280 | N42: 340 | O42: =N42*0.8 -> 272 | P42: 360 | Q42: =P42*0.8 -> 288 | R42: 360 | S42: =R42*0.8 -> 288 | T42: 375 | U42: =T42*0.8 -> 300
A43: DGK444D | B43: 313 | C43: 250 | D43: 313 | E43: 250 | F43: 313 | G43: 250 | H43: 290 | I43: =H43*0.8 -> 232 | J43: 360 | K43: =J43*0.8 -> 288 | L43: 360 | M43: =L43*0.8 -> 288 | N43: 350 | O43: =N43*0.8 -> 280 | P43: 375 | Q43: =P43*0.8 -> 300 | R43: 375 | S43: =R43*0.8 -> 300 | T43: 388 | U43: =T43*0.8 -> 310.4
A44: DG444E | B44: 325 | C44: =B44*0.8 -> 260 | D44: 325 | E44: =D44*0.8 -> 260 | F44: 325 | G44: =F44*0.8 -> 260 | H44: 325 | I44: =H44*0.8 -> 260 | J44: - | K44: - | L44: - | M44: - | N44: 381 | O44: =N44*0.8 -> 304.8 | P44: 400 | Q44: 320 | R44: 400 | S44: 320 | T44: 415 | U44: =T44*0.8 -> 332
...

Sheet 4P 1PH rating
A1: Dingol Generator Rating Table (4-pole 1-phase rating)
A2: Model | B2: Single Phase 50Hz 1500RPM | N2: Single Phase 60Hz 1800RPM
A3: Power Factor | B3: 0.8 | D3: 0.8 | F3: 0.8 | H3: 1 | J3: 1 | L3: 1 | N3: 0.8 | P3: 0.8 | R3: 0.8 | T3: 1 | V3: 1 | X3: 1
A4: Volts
A5: Series | B5: 220 | D5: 230 | F5: 240 | H5: 220 | J5: 230 | L5: 240 | N5: 220 | P5: 230 | R5: 240 | T5: 220 | V5: 230 | X5: 240
A6: Parallel | B6: =B5/2 -> 110 | D6: =D5/2 -> 115 | F6: =F5/2 -> 120 | H6: =H5/2 -> 110 | J6: =J5/2 -> 115 | L6: =L5/2 -> 120 | N6: =N5/2 -> 110 | P6: =P5/2 -> 115 | R6: =R5/2 -> 120 | T6: =T5/2 -> 110 | V6: =V5/2 -> 115 | X6: =X5/2 -> 120
A7: Winding No. | B7: 05 | D7: 05 | F7: 05 | H7: 05 | J7: 05 | L7: 05 | N7: 06 | P7: 06 | R7: 06 | T7: 06 | V7: 06 | X7: 06
A8: Rating | B8: KVA | C8: KW | D8: KVA | E8: KW | F8: KVA | G8: KW | H8: KVA | I8: KW | J8: KVA | K8: KW | L8: KVA | M8: KW | N8: KVA | O8: KW | P8: KVA | Q8: KW | R8: KVA | S8: KW | T8: KVA | U8: KW | V8: KVA | W8: KW | X8: KVA | Y8: KW
A9: DG164A | B9: 5.4 | C9: 4.3 | D9: 5.4 | E9: 4.3 | F9: 5.4 | G9: 4.3 | H9: 6.8 | I9: 6.8 | J9: 6.8 | K9: 6.8 | L9: 6.8 | M9: 6.8 | N9: 6.4 | O9: 5.1 | P9: 6.4 | Q9: 5.1 | R9: 6.4 | S9: 5.1 | T9: 8.2 | U9: 8.2 | V9: 8.2 | W9: 8.2 | X9: 8.2 | Y9: 8.2
A10: DG164B | B10: 7.4 | C10: 5.9 | D10: 7.4 | E10: 5.9 | F10: 7.4 | G10: 5.9 | H10: 8.4 | I10: 8.4 | J10: 8.4 | K10: 8.4 | L10: 8.4 | M10: 8.4 | N10: 8.8 | O10: 7 | P10: 8.8 | Q10: 7 | R10: 8.8 | S10: 7 | T10: 11 | U10: 11 | V10: 11 | W10: 11 | X10: 11 | Y10: 11
A11: DG164C | B11: 9 | C11: 7.2 | D11: 9 | E11: 7.2 | F11: 9 | G11: 7.2 | H11: 11 | I11: 11 | J11: 11 | K11: 11 | L11: 11 | M11: 11 | N11: 10.8 | O11: 8.6 | P11: 10.8 | Q11: 8.6 | R11: 10.8 | S11: 8.6 | T11: 13.5 | U11: 13.5 | V11: 13.5 | W11: 13.5 | X11: 13.5 | Y11: 13.5
A12: DG164D | B12: 10.8 | C12: 8.6 | D12: 10.8 | E12: 8.6 | F12: 10.8 | G12: 8.6 | H12: 13 | I12: 13 | J12: 13 | K12: 13 | L12: 13 | M12: 13 | N12: 13.5 | O12: 10.8 | P12: 13.5 | Q12: 10.8 | R12: 13.5 | S12: 10.8 | T12: 16.5 | U12: 16.5 | V12: 16.5 | W12: 16.5 | X12: 16.5 | Y12: 16.5
A14: DG184ES | B14: =C14/0.8 -> 12.5 | C14: 10 | D14: =E14/0.8 -> 12.5 | E14: 10 | F14: =G14/0.8 -> 12.5 | G14: 10 | H14: 14 | I14: 14 | J14: 14 | K14: 14 | L14: 14 | M14: 14 | N14: =O14/N3 -> 15 | O14: 12 | P14: =Q14/P3 -> 15 | Q14: 12 | R14: =S14/R3 -> 15 | S14: 12 | T14: 18 | U14: 18 | V14: 18 | W14: 18 | X14: 18 | Y14: 18
A15: DG184E | B15: 15 | C15: 12 | D15: 15 | E15: 12 | F15: 15 | G15: 12 | H15: 16.6 | I15: 16.6 | J15: 16.6 | K15: 16.6 | L15: 16.6 | M15: 16.6 | N15: 18.4 | O15: 14.7 | P15: 18.4 | Q15: 14.7 | R15: 18.4 | S15: 14.7 | T15: 21 | U15: 21 | V15: 21 | W15: 21 | X15: 21 | Y15: 21
A16: DG184F | B16: 18.5 | C16: 14.8 | D16: 18.5 | E16: 14.8 | F16: 18.5 | G16: 14.8 | H16: 20 | I16: 20 | J16: 20 | K16: 20 | L16: 20 | M16: 20 | N16: 21.9 | O16: 17.5 | P16: 21.9 | Q16: 17.5 | R16: 21.9 | S16: 17.5 | T16: 25.6 | U16: 25.6 | V16: 25.6 | W16: 25.6 | X16: 25.6 | Y16: 25.6
A17: DG184G | B17: 21 | C17: 16.8 | D17: 21 | E17: 16.8 | F17: 21 | G17: 16.8 | H17: 22.8 | I17: 22.8 | J17: 22.8 | K17: 22.8 | L17: 22.8 | M17: 22.8 | N17: 25 | O17: 20 | P17: 25 | Q17: 20 | R17: 25 | S17: 20 | T17: 30 | U17: 30 | V17: 30.8 | W17: 30.8 | X17: 30.8 | Y17: 30.8
A18: DG184H | B18: 25 | C18: 20 | D18: 25 | E18: 20 | F18: 25 | G18: 20 | H18: 27 | I18: 27 | J18: 27 | K18: 27 | L18: 27 | M18: 27 | N18: 31.3 | O18: 25 | P18: 31.3 | Q18: 25 | R18: 31.3 | S18: 25 | T18: 35 | U18: 35 | V18: 35 | W18: 35 | X18: 35 | Y18: 35
A19: DG184J | B19: 28 | C19: 22.4 | D19: 28 | E19: 22.4 | F19: 28 | G19: 22.4 | H19: 30 | I19: 30 | J19: 30 | K19: 30 | L19: 30 | M19: 30 | N19: 35 | O19: 28 | P19: 35 | Q19: 28 | R19: 35 | S19: 28 | T19: 40 | U19: 40 | V19: 40 | W19: 40 | X19: 40 | Y19: 40
A21: DG224C | B21: 28 | C21: 22.4 | D21: 28 | E21: 22.4 | F21: 28 | G21: 22.4 | H21: 28 | I21: 28 | J21: 28 | K21: 28 | L21: 28 | M21: 28 | N21: 37.5 | O21: 30 | P21: 37.5 | Q21: 30 | R21: 37.5 | S21: 30 | T21: 37.5 | U21: 37.5 | V21: 37.5 | W21: 37.5 | X21: 37.5 | Y21: 37.5
A22: DG224D | B22: 35 | C22: 28 | D22: 35 | E22: 28 | F22: 35 | G22: 28 | H22: 35 | I22: 35 | J22: 35 | K22: 35 | L22: 35 | M22: 35 | N22: 44 | O22: 35 | P22: 44 | Q22: 35 | R22: 44 | S22: 35 | T22: 44 | U22: 44 | V22: 44 | W22: 44 | X22: 44 | Y22: 44
A23: DG224E | B23: 40 | C23: 32 | D23: 40 | E23: 32 | F23: 40 | G23: 32 | H23: 40 | I23: 40 | J23: 40 | K23: 40 | L23: 40 | M23: 40 | N23: 50 | O23: 40 | P23: 50 | Q23: 40 | R23: 50 | S23: 40 | T23: 50 | U23: 50 | V23: 50 | W23: 50 | X23: 50 | Y23: 50
A24: DG224F | B24: 50 | C24: 40 | D24: 50 | E24: 40 | F24: 50 | G24: 40 | H24: 50 | I24: 50 | J24: 50 | K24: 50 | L24: 50 | M24: 50 | N24: 60 | O24: 48 | P24: 60 | Q24: 48 | R24: 60 | S24: 48 | T24: 60 | U24: 60 | V24: 60 | W24: 60 | X24: 60 | Y24: 60
A25: DG224G | B25: 60 | C25: 48 | D25: 60 | E25: 48 | F25: 60 | G25: 48 | H25: 60 | I25: 60 | J25: 60 | K25: 60 | L25: 60 | M25: 60 | N25: 70 | O25: 56 | P25: 70 | Q25: 56 | R25: 70 | S25: 56 | T25: 75 | U25: 75 | V25: 75 | W25: 75 | X25: 75 | Y25: 75
A27: DG274C | B27: 66 | C27: 52.8 | D27: 66 | E27: 52.8 | F27: 66 | G27: 52.8 | H27: 66 | I27: 66 | J27: 66 | K27: 66 | L27: 66 | M27: 66 | N27: 84 | O27: 67 | P27: 84 | Q27: 67 | R27: 84 | S27: 67 | T27: 90 | U27: 90 | V27: 90 | W27: 90 | X27: 90 | Y27: 90
A28: DG274D | B28: 74 | C28: 59.2 | D28: 74 | E28: 59.2 | F28: 74 | G28: 59.2 | H28: 74 | I28: 74 | J28: 74 | K28: 74 | L28: 74 | M28: 74 | N28: 96 | O28: 77 | P28: 96 | Q28: 77 | R28: 96 | S28: 77 | T28: 100 | U28: 100 | V28: 100 | W28: 100 | X28: 100 | Y28: 100
A29: DG274E | B29: 94 | C29: 75.2 | D29: 94 | E29: 75.2 | F29: 94 | G29: 75 | H29: 94 | I29: 94 | J29: 94 | K29: 94 | L29: 94 | M29: 94 | N29: 112 | O29: 90 | P29: 112 | Q29: 90 | R29: 112 | S29: 90 | T29: 115 | U29: 115 | V29: 115 | W29: 115 | X29: 115 | Y29: 115
A30: DG274EL | B30: =C30/0.8 -> 100 | C30: 80 | D30: =E30/0.8 -> 100 | E30: 80 | F30: =G30/0.8 -> 100 | G30: 80 | H30: 100 | I30: 100 | J30: 100 | K30: 100 | L30: 100 | M30: 100 | N30: =O30/0.8 -> 120 | O30: 96 | P30: =Q30/0.8 -> 120 | Q30: 96 | R30: =S30/0.8 -> 120 | S30: 96 | T30: 120 | U30: 120 | V30: 120 | W30: 120 | X30: 120 | Y30: 120
A31: DG274F | B31: 110 | C31: 88 | D31: 110 | E31: 88 | F31: 110 | G31: 88 | H31: 110 | I31: 110 | J31: 110 | K31: 110 | L31: 110 | M31: 110 | N31: 135 | O31: 108 | P31: 135 | Q31: 108 | R31: 135 | S31: 108 | T31: 135 | U31: 135 | V31: 135 | W31: 135 | X31: 135 | Y31: 135
A32: DG274G | B32: 120 | C32: 96 | D32: 120 | E32: 96 | F32: 120 | G32: 96 | H32: 120 | I32: 120 | J32: 120 | K32: 120 | L32: 120 | M32: 120 | N32: 150 | O32: 120 | P32: 150 | Q32: 120 | R32: 150 | S32: 120 | T32: 150 | U32: 150 | V32: 150 | W32: 150 | X32: 150 | Y32: 150
A33: DG274H | B33: 140 | C33: 112 | D33: 140 | E33: 112 | F33: 140 | G33: 112 | H33: 140 | I33: 140 | J33: 140 | K33: 140 | L33: 140 | M33: 140 | N33: 156.3 | O33: 125 | P33: 156.3 | Q33: 125 | R33: 156.3 | S33: 125 | T33: 156.3 | U33: 156.3 | V33: 156.3 | W33: 156.3 | X33: 156.3 | Y33: 156.3
A34: DG274J | B34: N/A | C34: N/A | D34: N/A | E34: N/A | F34: N/A | G34: N/A | H34: N/A | I34: N/A | J34: N/A | K34: N/A | L34: N/A | M34: N/A | N34: N/A | O34: N/A | P34: N/A | Q34: N/A | R34: N/A | S34: N/A | T34: N/A | U34: N/A | V34: N/A | W34: N/A | X34: N/A | Y34: N/A
A35: DG274K | B35: N/A | C35: N/A | D35: N/A | E35: N/A | F35: N/A | G35: N/A | H35: N/A | I35: N/A | J35: N/A | K35: N/A | L35: N/A | M35: N/A | N35: N/A | O35: N/A | P35: N/A | Q35: N/A | R35: N/A | S35: N/A | T35: N/A | U35: N/A | V35: N/A | W35: N/A | X35: N/A | Y35: N/A
A37: Notes：
A38: 1. The above rating is based on 40 degree C ambient and 125K temperature rising below 1000 meters altitude above sea.

Sheet 2P 3PH rating
A1: Dingol Generator Rating Table (2-pole 3-phase rating)
A2: Model | B2: Three Phase 50Hz 3000PM | J2: Three Phase 60Hz 3600RPM
A3: Power Factor | B3: 0.8 | D3: 0.8 | F3: 0.8 | H3: 0.8 | J3: 0.8 | L3: 0.8 | N3: 0.8 | P3: 0.8
A4: Volts
A5: Series Star | B5: 380 | D5: 400 | F5: 415 | H5: 440 | J5: 416 | L5: 440 | N5: 460 | P5: 480
A6: Parallel Star | B6: 190 | D6: 200 | F6: 208 | H6: 220 | J6: 208 | L6: 220 | N6: 230 | P6: 240
A7: Series Delta | B7: 220 | D7: 230 | F7: 240 | H7: 254 | J7: 240 | L7: 254 | N7: 266 | P7: 277
A8: Winding No. | B8: 11 | D8: 11 | F8: 11 | H8: 11 | J8: 11 | L8: 11 | N8: 11 | P8: 11
A9: Rating | B9: KVA | C9: KW | D9: KVA | E9: KW | F9: KVA | G9: KW | H9: KVA | I9: KW | J9: KVA | K9: KW | L9: KVA | M9: KW | N9: KVA | O9: KW | P9: KVA | Q9: KW
A10: DG162D | B10: 12.5 | C10: 10 | D10: 12.5 | E10: 10 | F10: 12.5 | G10: 10 | H10: 12 | I10: =H10*0.8 -> 9.6 | J10: 14.7 | K10: 11.8 | L10: 15.6 | M10: 12.5 | N10: 15.6 | O10: 12.5 | P10: 15.6 | Q10: 12.5
A11: DG162E | B11: 15 | C11: 12 | D11: 15 | E11: 12 | F11: 15 | G11: 12 | H11: 14.5 | I11: =H11*0.8 -> 11.6 | J11: 17.8 | K11: 14.2 | L11: 18.8 | M11: 15 | N11: 18.8 | O11: 15 | P11: 18.8 | Q11: 15
A12: DG162F | B12: 17.5 | C12: 14 | D12: 17.5 | E12: 14 | F12: 17.5 | G12: 14 | H12: 16.5 | I12: =H12*0.8 -> 13.2 | J12: 20.8 | K12: 16.6 | L12: 21.9 | M12: 17.5 | N12: 21.9 | O12: 17.5 | P12: 21.9 | Q12: 17.5
A13: DG162G | B13: 25 | C13: 20 | D13: 25 | E13: 20 | F13: 25 | G13: 20 | H13: 22.5 | I13: =H13*0.8 -> 18 | J13: 29.6 | K13: 23.7 | L13: 31.3 | M13: 25 | N13: 31.3 | O13: 25 | P13: 31.3 | Q13: 25
A15: DG182H | B15: 30 | C15: 24 | D15: 30 | E15: 24 | F15: 30 | G15: 24 | H15: 27 | I15: =H15*0.8 -> 21.6 | J15: 33 | K15: 26.4 | L15: 35 | M15: 28 | N15: 35 | O15: 28 | P15: 35 | Q15: 28
A16: DG182J | B16: 35 | C16: 28 | D16: 35 | E16: 28 | F16: 35 | G16: 28 | H16: 30.8 | I16: =H16*0.8 -> 24.64 | J16: 37.8 | K16: 30.2 | L16: 40 | M16: 32 | N16: 40 | O16: 32 | P16: 40 | Q16: 32
A17: DG182K | B17: 37.5 | C17: 30 | D17: 37.5 | E17: 30 | F17: 37.5 | G17: 30 | H17: 35 | I17: =H17*0.8 -> 28 | J17: 44.3 | K17: 35.4 | L17: 46.9 | M17: 37.5 | N17: 46.9 | O17: 37.5 | P17: 46.9 | Q17: 37.5
A24: Notes：
A25: 1. The above rating is based on 40 degree C ambient and 125K temperature rising below 1000 meters altitude above sea.

Sheet 2P 1PH rating
A1: Dingol Generator Rating Table (2-pole 1-phase rating)
A2: Model | B2: Single Phase 50Hz 3000RPM | N2: Single Phase 60Hz 3600RPM
A3: Power Factor | B3: 0.8 | D3: 0.8 | F3: 0.8 | H3: 1 | J3: 1 | L3: 1 | N3: 0.8 | P3: 0.8 | R3: 0.8 | T3: 1 | V3: 1 | X3: 1
A4: Volts
A5: Series | B5: 220 | D5: 230 | F5: 240 | H5: 220 | J5: 230 | L5: 240 | N5: 220 | P5: 230 | R5: 240 | T5: 220 | V5: 230 | X5: 240
A6: Parallel | B6: =B5/2 -> 110 | D6: =D5/2 -> 115 | F6: =F5/2 -> 120 | H6: =H5/2 -> 110 | J6: =J5/2 -> 115 | L6: =L5/2 -> 120 | N6: =N5/2 -> 110 | P6: =P5/2 -> 115 | R6: =R5/2 -> 120 | T6: =T5/2 -> 110 | V6: =V5/2 -> 115 | X6: =X5/2 -> 120
A7: Winding No. | B7: 05 | D7: 05 | F7: 05 | H7: 05 | J7: 05 | L7: 05 | N7: 06 | P7: 06 | R7: 06 | T7: 06 | V7: 06 | X7: 06
A8: Rating | B8: KVA | C8: KW | D8: KVA | E8: KW | F8: KVA | G8: KW | H8: KVA | I8: KW | J8: KVA | K8: KW | L8: KVA | M8: KW | N8: KVA | O8: KW | P8: KVA | Q8: KW | R8: KVA | S8: KW | T8: KVA | U8: KW | V8: KVA | W8: KW | X8: KVA | Y8: KW
A9: DG162D | B9: 8.4 | C9: 6.7 | D9: 8.4 | E9: 6.7 | F9: 8.4 | G9: 6.7 | H9: 9.6 | I9: 9.6 | J9: 9.6 | K9: 9.6 | L9: 10 | M9: 10 | N9: 10 | O9: 8 | P9: 10 | Q9: 8 | R9: 10 | S9: 8 | T9: 11.5 | U9: 11.5 | V9: 11.5 | W9: 11.5 | X9: 12 | Y9: 12
A10: DG162E | B10: 10 | C10: 8 | D10: 10 | E10: 8 | F10: 10 | G10: 8 | H10: 11.5 | I10: 11.5 | J10: 11.5 | K10: 11.5 | L10: 12 | M10: 12 | N10: 12.4 | O10: 9.9 | P10: 12.4 | Q10: 9.9 | R10: 12.4 | S10: 9.9 | T10: 12.8 | U10: 12.8 | V10: 12.8 | W10: 12.8 | X10: 15 | Y10: 15
A11: DG162F | B11: 11.8 | C11: 9.4 | D11: 11.8 | E11: 9.4 | F11: 11.8 | G11: 9.4 | H11: 13.5 | I11: 13.5 | J11: 13.5 | K11: 13.5 | L11: 14.5 | M11: 14.5 | N11: 14.4 | O11: 11.5 | P11: 14.4 | Q11: 11.5 | R11: 14.4 | S11: 11.5 | T11: 16.6 | U11: 16.6 | V11: 16.6 | W11: 16.6 | X11: 17.5 | Y11: 17.5
A12: DG162G | B12: 16.8 | C12: 13.4 | D12: 16.8 | E12: 13.4 | F12: 16.8 | G12: 13.4 | H12: 17.5 | I12: 17.5 | J12: 18.5 | K12: 18.5 | L12: 19.3 | M12: 19.3 | N12: 20.6 | O12: 16.5 | P12: 20.6 | Q12: 16.5 | R12: 20.6 | S12: 16.5 | T12: 23.7 | U12: 23.7 | V12: 23.7 | W12: 23.7 | X12: 22 | Y12: 22
A14: DG182H | B14: 20 | C14: 16 | D14: 20 | E14: 16 | F14: 20 | G14: 16 | H14: 20 | I14: 20 | J14: 20 | K14: 20 | L14: 20 | M14: 20 | N14: 24.8 | O14: 19.8 | P14: 24.8 | Q14: 19.8 | R14: 24.8 | S14: 19.8 | T14: 24.8 | U14: 24.8 | V14: 24.8 | W14: 24.8 | X14: 24.8 | Y14: 24.8
A15: DG182J | B15: 23.5 | C15: 18.8 | D15: 23.5 | E15: 18.8 | F15: 23.5 | G15: 18.8 | H15: 23.5 | I15: 23.5 | J15: 23.5 | K15: 23.5 | L15: 23.5 | M15: 23.5 | N15: 28.9 | O15: 23.1 | P15: 28.9 | Q15: 23.1 | R15: 28.9 | S15: 23.1 | T15: 28.9 | U15: 28.9 | V15: 28.9 | W15: 28.9 | X15: 28.9 | Y15: 28.9
A16: DG182K | B16: 25 | C16: 20 | D16: 25 | E16: 20 | F16: 25 | G16: 20 | H16: 25 | I16: 25 | J16: 25 | K16: 25 | L16: 25 | M16: 25 | N16: 31 | O16: 24.8 | P16: 31 | Q16: 24.8 | R16: 31 | S16: 24.8 | T16: 31 | U16: 31 | V16: 31 | W16: 31 | X16: 31 | Y16: 31
A18: Notes：
A19: 1. The above rating is based on 40 degree C ambient and 125K temperature rising below 1000 meters altitude above sea.

Sheet 4P 3PH 40SB
A1: Dingol Generator Rating Table (4-pole 3-phase rating)
A2: Model | B2: Three Phase 50Hz 1500RPM | J2: Three Phase 60Hz 1800RPM
A3: Power Factor | B3: 0.8 | D3: 0.8 | F3: 0.8 | H3: 0.8 | J3: 0.8 | L3: 0.8 | N3: 0.8 | P3: 0.8 | R3: 0.8 | T3: 0.8
A4: Volts
A5: Star(W12&W13) | B5: 380 | D5: 400 | F5: 415 | H5: 440 | J5: 380-416 | N5: 416 | P5: 440 | R5: 460 | T5: 480
A6: Delta(W12&W13) | B6: 220 | D6: 230 | F6: 240 | H6: 254 | J6: 220-240 | N6: 240 | P6: 254 | R6: 266 | T6: 277
A7: Series Star(W11&W14) | B7: 380 | D7: 400 | F7: 415 | H7: 440 | J7: - | L7: 380-416 | N7: 416 | P7: 440 | R7: 460 | T7: 480
A8: Parallel Star(W11&W14) | B8: 190 | D8: 200 | F8: 208 | H8: 220 | J8: - | L8: 190-208 | N8: 208 | P8: 220 | R8: 230 | T8: 240
A9: Series Delta | B9: 220 | D9: 230 | F9: 240 | H9: 254 | J9: - | L9: 220-240 | N9: 240 | P9: 254 | R9: 266 | T9: 277
A10: Winding No. | B10: 11 | D10: 11 | F10: 11 | H10: 11 | J10: 13 | L10: 14 | N10: 11 | P10: 11 | R10: 11 | T10: 11
A11: Rating | B11: KVA | C11: KW | D11: KVA | E11: KW | F11: KVA | G11: KW | H11: KVA | I11: KW | J11: KVA | K11: KW | L11: KVA | M11: KW | N11: KVA | O11: KW | P11: KVA | Q11: KW | R11: KVA | S11: KW | T11: KVA | U11: KW
A12: DG164A | B12: - | C12: - | D12: - | E12: - | F12: - | G12: - | H12: - | I12: - | J12: - | K12: - | L12: - | M12: - | N12: - | O12: - | P12: - | Q12: - | R12: - | S12: - | T12: - | U12: -
A13: DG164B | B13: - | C13: - | D13: - | E13: - | F13: - | G13: - | H13: - | I13: - | J13: - | K13: - | L13: - | M13: - | N13: - | O13: - | P13: - | Q13: - | R13: - | S13: - | T13: - | U13: -
A14: DG164C | B14: - | C14: - | D14: - | E14: - | F14: - | G14: - | H14: - | I14: - | J14: - | K14: - | L14: - | M14: - | N14: - | O14: - | P14: - | Q14: - | R14: - | S14: - | T14: - | U14: -
A15: DG164D | B15: - | C15: - | D15: - | E15: - | F15: - | G15: - | H15: - | I15: - | J15: - | K15: - | L15: - | M15: - | N15: - | O15: - | P15: - | Q15: - | R15: - | S15: - | T15: - | U15: -
A17: DG184ES | B17: - | C17: - | D17: - | E17: - | F17: - | G17: - | H17: - | I17: - | J17: - | K17: - | L17: - | M17: - | N17: - | O17: - | P17: - | Q17: - | R17: - | S17: - | T17: - | U17: -
A18: DG184E | B18: - | C18: - | D18: - | E18: - | F18: - | G18: - | H18: - | I18: - | J18: - | K18: - | L18: - | M18: - | N18: - | O18: - | P18: - | Q18: - | R18: - | S18: - | T18: - | U18: -
A19: DG184F | B19: 29 | C19: =B19*0.8 -> 23.2 | D19: 29 | E19: =D19*0.8 -> 23.2 | F19: 29 | G19: =F19*0.8 -> 23.2 | H19: 23.7 | I19: =H19*0.8 -> 18.96 | J19: - | K19: - | L19: - | M19: - | N19: 33.8 | O19: =N19*0.8 -> 27.04 | P19: 35 | Q19: =P19*0.8 -> 28 | R19: 35 | S19: =R19*0.8 -> 28 | T19: 37.5 | U19: =T19*0.8 -> 30
A20: DG184G | B20: 32.5 | C20: =B20*0.8 -> 26 | D20: 32.5 | E20: =D20*0.8 -> 26 | F20: 32.5 | G20: 25 | H20: 28.6 | I20: =H20*0.8 -> 22.88 | J20: - | K20: - | L20: - | M20: - | N20: 36.3 | O20: =N20*0.8 -> 29.04 | P20: 38.8 | Q20: =P20*0.8 -> 31.04 | R20: 38.8 | S20: =R20*0.8 -> 31.04 | T20: 38.8 | U20: =T20*0.8 -> 31.04
A21: DG184H | B21: 39 | C21: =B21*0.8 -> 31.2 | D21: 39 | E21: =D21*0.8 -> 31.2 | F21: 39 | G21: =F21*0.8 -> 31.2 | H21: 33.8 | I21: =H21*0.8 -> 27.04 | J21: - | K21: - | L21: - | M21: - | N21: 45.9 | O21: =N21*0.8 -> 36.72 | P21: 48.5 | Q21: =P21*0.8 -> 38.8 | R21: 48.5 | S21: =R21*0.8 -> 38.8 | T21: 48.5 | U21: =T21*0.8 -> 38.8
A22: DG184J | B22: 41.5 | C22: =B22*0.8 -> 33.2 | D22: 44 | E22: =D22*0.8 -> 35.2 | F22: 41.5 | G22: =F22*0.8 -> 33.2 | H22: 36.3 | I22: =H22*0.8 -> 29.04 | J22: - | K22: - | L22: - | M22: - | N22: 49.2 | O22: =N22*0.8 -> 39.36 | P22: 52 | Q22: =P22*0.8 -> 41.6 | R22: 52 | S22: =R22*0.8 -> 41.6 | T22: 52 | U22: =T22*0.8 -> 41.6
A24: DG224C | B24: 45 | C24: =B24*0.8 -> 36 | D24: 45 | E24: =D24*0.8 -> 36 | F24: 45 | G24: =F24*0.8 -> 36 | H24: 31.7 | I24: =H24*0.8 -> 25.36 | J24: - | K24: - | L24: 58.1 | M24: =L24*0.8 -> 46.48 | N24: 53.1 | O24: =N24*0.8 -> 42.48 | P24: 55 | Q24: =P24*0.8 -> 44 | R24: 55 | S24: =R24*0.8 -> 44 | T24: 58.1 | U24: =T24*0.8 -> 46.48
A25: DG224D | B25: 53 | C25: =B25*0.8 -> 42.4 | D25: 53 | E25: =D25*0.8 -> 42.4 | F25: 53 | G25: =F25*0.8 -> 42.4 | H25: 39.1 | I25: =H25*0.8 -> 31.28 | J25: - | K25: - | L25: 65 | M25: =L25*0.8 -> 52 | N25: 62.5 | O25: =N25*0.8 -> 50 | P25: 65 | Q25: =P25*0.8 -> 52 | R25: 65 | S25: =R25*0.8 -> 52 | T25: 68.8 | U25: =T25*0.8 -> 55.04
A26: DG224E | B26: 61 | C26: =B26*0.8 -> 48.8 | D26: 61 | E26: =D26*0.8 -> 48.8 | F26: 61 | G26: =F26*0.8 -> 48.8 | H26: 45.8 | I26: =H26*0.8 -> 36.64 | J26: - | K26: - | L26: 73.8 | M26: =L26*0.8 -> 59.04 | N26: 70 | O26: =N26*0.8 -> 56 | P26: 73.8 | Q26: =P26*0.8 -> 59.04 | R26: 73.8 | S26: =R26*0.8 -> 59.04 | T26: 78.8 | U26: =T26*0.8 -> 63.04
A27: DG224F | B27: 77 | C27: =B27*0.8 -> 61.6 | D27: 77 | E27: =D27*0.8 -> 61.6 | F27: 77 | G27: =F27*0.8 -> 61.6 | H27: 58 | I27: =H27*0.8 -> 46.4 | J27: - | K27: - | L27: 89.4 | M27: =L27*0.8 -> 71.52 | N27: 88.8 | O27: =N27*0.8 -> 71.04 | P27: 92.5 | Q27: =P27*0.8 -> 74 | R27: 92.5 | S27: =R27*0.8 -> 74 | T27: 98.8 | U27: =T27*0.8 -> 79.04
A28: DG224G | B28: 87.5 | C28: =B28*0.8 -> 70 | D28: 87.5 | E28: =D28*0.8 -> 70 | F28: 87.5 | G28: =F28*0.8 -> 70 | H28: 76.9 | I28: =H28*0.8 -> 61.52 | J28: - | K28: - | L28: 102.5 | M28: =L28*0.8 -> 82 | N28: 98.1 | O28: =N28*0.8 -> 78.48 | P28: 102.5 | Q28: =P28*0.8 -> 82 | R28: 102.5 | S28: =R28*0.8 -> 82 | T28: 110 | U28: =T28*0.8 -> 88
A30: DG274C | B30: 106 | C30: =B30*0.8 -> 84.8 | D30: 106 | E30: =D30*0.8 -> 84.8 | F30: 106 | G30: =F30*0.8 -> 84.8 | H30: - | I30: - | J30: - | K30: - | L30: 127 | M30: =L30*0.8 -> 101.6 | N30: 116.3 | O30: =N30*0.8 -> 93.04 | P30: 125 | Q30: =P30*0.8 -> 100 | R30: 117.5 | S30: =R30*0.8 -> 94 | T30: 132.5 | U30: =T30*0.8 -> 106
A31: DG274D | B31: 130 | C31: =B31*0.8 -> 104 | D31: 130 | E31: =D31*0.8 -> 104 | F31: 130 | G31: =F31*0.8 -> 104 | H31: - | I31: - | J31: - | K31: - | L31: 140 | M31: =L31*0.8 -> 112 | N31: 140 | O31: =N31*0.8 -> 112 | P31: 150 | Q31: =P31*0.8 -> 120 | R31: 150 | S31: =R31*0.8 -> 120 | T31: 150 | U31: =T31*0.8 -> 120
A32: DG274E | B32: 145 | C32: =B32*0.8 -> 116 | D32: 145 | E32: =D32*0.8 -> 116 | F32: 145 | G32: =F32*0.8 -> 116 | H32: - | I32: - | J32: - | K32: - | L32: 170 | M32: =L32*0.8 -> 136 | N32: 170 | O32: =N32*0.8 -> 136 | P32: 175 | Q32: =P32*0.8 -> 140 | R32: 175 | S32: =R32*0.8 -> 140 | T32: 187.5 | U32: =T32*0.8 -> 150
A33: DG274EL | B33: 155 | C33: =B33*0.8 -> 124 | D33: 155 | E33: =D33*0.8 -> 124 | F33: 155 | G33: =F33*0.8 -> 124 | H33: - | I33: - | J33: - | K33: - | L33: - | M33: - | N33: 170 | O33: =N33*0.8 -> 136 | P33: 180 | Q33: =P33*0.8 -> 144 | R33: 180 | S33: =R33*0.8 -> 144 | T33: 190 | U33: =T33*0.8 -> 152
A34: DG274F | B34: 170 | C34: =B34*0.8 -> 136 | D34: 170 | E34: =D34*0.8 -> 136 | F34: 170 | G34: =F34*0.8 -> 136 | H34: - | I34: - | J34: - | K34: - | L34: 186 | M34: =L34*0.8 -> 148.8 | N34: 187.5 | O34: =N34*0.8 -> 150 | P34: 200 | Q34: =P34*0.8 -> 160 | R34: 200 | S34: =R34*0.8 -> 160 | T34: 212.5 | U34: =T34*0.8 -> 170
A35: DG274G | B35: 187 | C35: =B35*0.8 -> 149.6 | D35: 187 | E35: =D35*0.8 -> 149.6 | F35: 187 | G35: =F35*0.8 -> 149.6 | H35: - | I35: - | J35: - | K35: - | L35: 207.5 | M35: =L35*0.8 -> 166 | N35: 213 | O35: =N35*0.8 -> 170.4 | P35: 228.8 | Q35: =P35*0.8 -> 183.04 | R35: 228.8 | S35: =R35*0.8 -> 183.04 | T35: 246.8 | U35: =T35*0.8 -> 197.44
A36: DG274H | B36: 212 | C36: =B36*0.8 -> 169.6 | D36: 212 | E36: =D36*0.8 -> 169.6 | F36: 212 | G36: =F36*0.8 -> 169.6 | H36: - | I36: - | J36: - | K36: - | L36: 250 | M36: =L36*0.8 -> 200 | N36: 237 | O36: =N36*0.8 -> 189.6 | P36: 258.8 | Q36: =P36*0.8 -> 207.04 | R36: 258.8 | S36: =R36*0.8 -> 207.04 | T36: 275 | U36: =T36*0.8 -> 220
A37: DG274J | B37: 250 | C37: =B37*0.8 -> 200 | D37: 250 | E37: =D37*0.8 -> 200 | F37: 250 | G37: =F37*0.8 -> 200 | H37: - | I37: - | J37: - | K37: - | L37: - | M37: - | N37: 288 | O37: =N37*0.8 -> 230.4 | P37: 300 | Q37: =P37*0.8 -> 240 | R37: 313 | S37: =R37*0.8 -> 250.4 | T37: 319 | U37: =T37*0.8 -> 255.2
A38: DG274K | B38: 265 | C38: =B38*0.8 -> 212 | D38: 265 | E38: =D38*0.8 -> 212 | F38: 265 | G38: =F38*0.8 -> 212 | H38: - | I38: - | J38: - | K38: - | L38: 319 | M38: =L38*0.8 -> 255.2 | N38: 304 | O38: =N38*0.8 -> 243.2 | P38: 312.5 | Q38: =P38*0.8 -> 250 | R38: 331.3 | S38: =R38*0.8 -> 265.04 | T38: 331.3 | U38: =T38*0.8 -> 265.04
A40: DG444C | B40: 259 | C40: =B40*0.8 -> 207.2 | D40: 259 | E40: =D40*0.8 -> 207.2 | F40: 259 | G40: =F40*0.8 -> 207.2 | H40: 259 | I40: =H40*0.8 -> 207.2 | J40: 319 | K40: =J40*0.8 -> 255.2 | L40: 319 | M40: =L40*0.8 -> 255.2 | N40: 300 | O40: =N40*0.8 -> 240 | P40: 313 | Q40: =P40*0.8 -> 250.4 | R40: 319 | S40: =R40*0.8 -> 255.2 | T40: 332 | U40: =T40*0.8 -> 265.6
A41: DG444D | B41: 313 | C41: =B41*0.8 -> 250.4 | D41: 313 | E41: =D41*0.8 -> 250.4 | F41: 313 | G41: =F41*0.8 -> 250.4 | H41: 295 | I41: =H41*0.8 -> 236 | J41: 375 | K41: =J41*0.8 -> 300 | L41: 375 | M41: =L41*0.8 -> 300 | N41: 356 | O41: =N41*0.8 -> 284.8 | P41: 375 | Q41: =P41*0.8 -> 300 | R41: 388 | S41: =R41*0.8 -> 310.4 | T41: 400 | U41: =T41*0.8 -> 320
A42: DGK444D | B42: 320 | C42: =B42*0.8 -> 256 | D42: 320 | E42: =D42*0.8 -> 256 | F42: 320 | G42: =F42*0.8 -> 256 | H42: 310 | I42: =H42*0.8 -> 248 | J42: 375 | K42: =J42*0.8 -> 300 | L42: 375 | M42: =L42*0.8 -> 300 | N42: 363 | O42: =N42*0.8 -> 290.4 | P42: 384 | Q42: =P42*0.8 -> 307.2 | R42: 400 | S42: =R42*0.8 -> 320 | T42: 400 | U42: =T42*0.8 -> 320
A43: DG444E | B43: 345 | C43: =B43*0.8 -> 276 | D43: 345 | E43: =D43*0.8 -> 276 | F43: 345 | G43: =F43*0.8 -> 276 | H43: 345 | I43: =H43*0.8 -> 276 | J43: - | K43: - | L43: - | M43: - | N43: 406 | O43: =N43*0.8 -> 324.8 | P43: 419 | Q43: =P43*0.8 -> 335.2 | R43: 431 | S43: =R43*0.8 -> 344.8 | T43: 444 | U43: =T43*0.8 -> 355.2
A44: DGK444E | B44: 368 | C44: =B44*0.8 -> 294.4 | D44: 368 | E44: =D44*0.8 -> 294.4 | F44: 368 | G44: =F44*0.8 -> 294.4 | H44: 368 | I44: =H44*0.8 -> 294.4 | J44: - | K44: - | L44: - | M44: - | N44: 417 | O44: =N44*0.8 -> 333.6 | P44: 442 | Q44: =P44*0.8 -> 353.6 | R44: 460 | S44: =R44*0.8 -> 368 | T44: 460 | U44: =T44*0.8 -> 368
...

Sheet 4P 3PH 27SB
A1: Dingol Generator Rating Table (4-pole 3-phase rating)
A2: Model | B2: Three Phase 50Hz 1500RPM | J2: Three Phase 60Hz 1800RPM
A3: Power Factor | B3: 0.8 | D3: 0.8 | F3: 0.8 | H3: 0.8 | J3: 0.8 | L3: 0.8 | N3: 0.8 | P3: 0.8 | R3: 0.8 | T3: 0.8
A4: Volts
A5: Star(W12&W13) | B5: 380 | D5: 400 | F5: 415 | H5: 440 | J5: 380-416 | N5: 416 | P5: 440 | R5: 460 | T5: 480
A6: Delta(W12&W13) | B6: 220 | D6: 230 | F6: 240 | H6: 254 | J6: 220-240 | N6: 240 | P6: 254 | R6: 266 | T6: 277
A7: Series Star(W11&W14) | B7: 380 | D7: 400 | F7: 415 | H7: 440 | J7: - | L7: 380-416 | N7: 416 | P7: 440 | R7: 460 | T7: 480
A8: Parallel Star(W11&W14) | B8: 190 | D8: 200 | F8: 208 | H8: 220 | J8: - | L8: 190-208 | N8: 208 | P8: 220 | R8: 230 | T8: 240
A9: Series Delta | B9: 220 | D9: 230 | F9: 240 | H9: 254 | J9: - | L9: 220-240 | N9: 240 | P9: 254 | R9: 266 | T9: 277
A10: Winding No. | B10: 11 | D10: 11 | F10: 11 | H10: 11 | J10: 13 | L10: 14 | N10: 11 | P10: 11 | R10: 11 | T10: 11
A11: Rating | B11: KVA | C11: KW | D11: KVA | E11: KW | F11: KVA | G11: KW | H11: KVA | I11: KW | J11: KVA | K11: KW | L11: KVA | M11: KW | N11: KVA | O11: KW | P11: KVA | Q11: KW | R11: KVA | S11: KW | T11: KVA | U11: KW
A12: DG164A | B12: - | C12: - | D12: - | E12: - | F12: - | G12: - | H12: - | I12: - | J12: - | K12: - | L12: - | M12: - | N12: - | O12: - | P12: - | Q12: - | R12: - | S12: - | T12: - | U12: -
A13: DG164B | B13: - | C13: - | D13: - | E13: - | F13: - | G13: - | H13: - | I13: - | J13: - | K13: - | L13: - | M13: - | N13: - | O13: - | P13: - | Q13: - | R13: - | S13: - | T13: - | U13: -
A14: DG164C | B14: - | C14: - | D14: - | E14: - | F14: - | G14: - | H14: - | I14: - | J14: - | K14: - | L14: - | M14: - | N14: - | O14: - | P14: - | Q14: - | R14: - | S14: - | T14: - | U14: -
A15: DG164D | B15: - | C15: - | D15: - | E15: - | F15: - | G15: - | H15: - | I15: - | J15: - | K15: - | L15: - | M15: - | N15: - | O15: - | P15: - | Q15: - | R15: - | S15: - | T15: - | U15: -
A17: DG184ES | B17: - | C17: - | D17: - | E17: - | F17: - | G17: - | H17: - | I17: - | J17: - | K17: - | L17: - | M17: - | N17: - | O17: - | P17: - | Q17: - | R17: - | S17: - | T17: - | U17: -
A18: DG184E | B18: - | C18: - | D18: - | E18: - | F18: - | G18: - | H18: - | I18: - | J18: - | K18: - | L18: - | M18: - | N18: - | O18: - | P18: - | Q18: - | R18: - | S18: - | T18: - | U18: -
A19: DG184F | B19: 30 | C19: =B19*0.8 -> 24 | D19: 30 | E19: =D19*0.8 -> 24 | F19: 30 | G19: =F19*0.8 -> 24 | H19: 24.5 | I19: =H19*0.8 -> 19.6 | J19: - | K19: - | L19: - | M19: - | N19: 34.4 | O19: =N19*0.8 -> 27.52 | P19: 35.6 | Q19: =P19*0.8 -> 28.48 | R19: 35.6 | S19: =R19*0.8 -> 28.48 | T19: 38.8 | U19: =T19*0.8 -> 31.04
A20: DG184G | B20: 33 | C20: =B20*0.8 -> 26.4 | D20: 33 | E20: =D20*0.8 -> 26.4 | F20: 33 | G20: 25 | H20: 29 | I20: =H20*0.8 -> 23.2 | J20: - | K20: - | L20: - | M20: - | N20: 36.9 | O20: =N20*0.8 -> 29.52 | P20: 40 | Q20: =P20*0.8 -> 32 | R20: 40 | S20: =R20*0.8 -> 32 | T20: 40 | U20: =T20*0.8 -> 32
A21: DG184H | B21: 40 | C21: =B21*0.8 -> 32 | D21: 40 | E21: =D21*0.8 -> 32 | F21: 40 | G21: =F21*0.8 -> 32 | H21: 34.7 | I21: =H21*0.8 -> 27.76 | J21: - | K21: - | L21: - | M21: - | N21: 47.3 | O21: =N21*0.8 -> 37.84 | P21: 50 | Q21: =P21*0.8 -> 40 | R21: 50 | S21: =R21*0.8 -> 40 | T21: 50 | U21: =T21*0.8 -> 40
A22: DG184J | B22: 42.5 | C22: =B22*0.8 -> 34 | D22: 42.5 | E22: =D22*0.8 -> 34 | F22: 42.5 | G22: =F22*0.8 -> 34 | H22: 37.2 | I22: =H22*0.8 -> 29.76 | J22: - | K22: - | L22: - | M22: - | N22: 50.6 | O22: =N22*0.8 -> 40.48 | P22: 53.5 | Q22: =P22*0.8 -> 42.8 | R22: 53.5 | S22: =R22*0.8 -> 42.8 | T22: 53.5 | U22: =T22*0.8 -> 42.8
A24: DG224C | B24: 46.8 | C24: =B24*0.8 -> 37.44 | D24: 46.8 | E24: =D24*0.8 -> 37.44 | F24: 46.8 | G24: =F24*0.8 -> 37.44 | H24: 33 | I24: =H24*0.8 -> 26.4 | J24: - | K24: - | L24: 60 | M24: =L24*0.8 -> 48 | N24: 55 | O24: =N24*0.8 -> 44 | P24: 56.3 | Q24: =P24*0.8 -> 45.04 | R24: 56.3 | S24: =R24*0.8 -> 45.04 | T24: 60 | U24: =T24*0.8 -> 48
A25: DG224D | B25: 55 | C25: =B25*0.8 -> 44 | D25: 55 | E25: =D25*0.8 -> 44 | F25: 55 | G25: =F25*0.8 -> 44 | H25: 41.2 | I25: =H25*0.8 -> 32.96 | J25: - | K25: - | L25: 66.3 | M25: =L25*0.8 -> 53.04 | N25: 65 | O25: =N25*0.8 -> 52 | P25: 66.3 | Q25: =P25*0.8 -> 53.04 | R25: 66.3 | S25: =R25*0.8 -> 53.04 | T25: 71.3 | U25: =T25*0.8 -> 57.04
A26: DG224E | B26: 63 | C26: =B26*0.8 -> 50.4 | D26: 63 | E26: =D26*0.8 -> 50.4 | F26: 63 | G26: =F26*0.8 -> 50.4 | H26: 47.3 | I26: =H26*0.8 -> 37.84 | J26: - | K26: - | L26: 75 | M26: =L26*0.8 -> 60 | N26: 72.5 | O26: =N26*0.8 -> 58 | P26: 75 | Q26: =P26*0.8 -> 60 | R26: 75 | S26: =R26*0.8 -> 60 | T26: 80 | U26: =T26*0.8 -> 64
A27: DG224F | B27: 80 | C27: =B27*0.8 -> 64 | D27: 80 | E27: =D27*0.8 -> 64 | F27: 80 | G27: =F27*0.8 -> 64 | H27: 60.4 | I27: =H27*0.8 -> 48.32 | J27: - | K27: - | L27: 92 | M27: =L27*0.8 -> 73.6 | N27: 91.9 | O27: =N27*0.8 -> 73.52 | P27: 95 | Q27: =P27*0.8 -> 76 | R27: 95 | S27: =R27*0.8 -> 76 | T27: 102.5 | U27: =T27*0.8 -> 82
A28: DG224G | B28: 90.8 | C28: =B28*0.8 -> 72.64 | D28: 90.8 | E28: =D28*0.8 -> 72.64 | F28: 90.8 | G28: =F28*0.8 -> 72.64 | H28: 80.1 | I28: =H28*0.8 -> 64.08 | J28: - | K28: - | L28: 106.3 | M28: =L28*0.8 -> 85.04 | N28: 101.3 | O28: =N28*0.8 -> 81.04 | P28: 106.3 | Q28: =P28*0.8 -> 85.04 | R28: 106.3 | S28: =R28*0.8 -> 85.04 | T28: 113.8 | U28: =T28*0.8 -> 91.04
A30: DG274C | B30: 110 | C30: =B30*0.8 -> 88 | D30: 110 | E30: =D30*0.8 -> 88 | F30: 110 | G30: =F30*0.8 -> 88 | H30: - | I30: - | J30: - | K30: - | L30: 132 | M30: =L30*0.8 -> 105.6 | N30: 120 | O30: =N30*0.8 -> 96 | P30: 127.5 | Q30: =P30*0.8 -> 102 | R30: 127.5 | S30: =R30*0.8 -> 102 | T30: 137.5 | U30: =T30*0.8 -> 110
A31: DG274D | B31: 135 | C31: =B31*0.8 -> 108 | D31: 135 | E31: =D31*0.8 -> 108 | F31: 135 | G31: =F31*0.8 -> 108 | H31: - | I31: - | J31: - | K31: - | L31: 140 | M31: =L31*0.8 -> 112 | N31: 140 | O31: =N31*0.8 -> 112 | P31: 150 | Q31: =P31*0.8 -> 120 | R31: 150 | S31: =R31*0.8 -> 120 | T31: 150 | U31: =T31*0.8 -> 120
A32: DG274E | B32: 150 | C32: =B32*0.8 -> 120 | D32: 150 | E32: =D32*0.8 -> 120 | F32: 150 | G32: =F32*0.8 -> 120 | H32: - | I32: - | J32: - | K32: - | L32: 175 | M32: =L32*0.8 -> 140 | N32: 175 | O32: =N32*0.8 -> 140 | P32: 181.3 | Q32: =P32*0.8 -> 145.04 | R32: 181.3 | S32: =R32*0.8 -> 145.04 | T32: 193.8 | U32: =T32*0.8 -> 155.04
A33: DG274EL | B33: 160 | C33: =B33*0.8 -> 128 | D33: 160 | E33: =D33*0.8 -> 128 | F33: 160 | G33: =F33*0.8 -> 128 | H33: - | I33: - | J33: - | K33: - | L33: - | M33: - | N33: 170 | O33: =N33*0.8 -> 136 | P33: 180 | Q33: 144 | R33: 180 | S33: 144 | T33: 190 | U33: =T33*0.8 -> 152
A34: DG274F | B34: 175 | C34: =B34*0.8 -> 140 | D34: 175 | E34: =D34*0.8 -> 140 | F34: 175 | G34: =F34*0.8 -> 140 | H34: - | I34: - | J34: - | K34: - | L34: 190 | M34: =L34*0.8 -> 152 | N34: 192.5 | O34: =N34*0.8 -> 154 | P34: 206.3 | Q34: =P34*0.8 -> 165.04 | R34: 206.3 | S34: =R34*0.8 -> 165.04 | T34: 218.8 | U34: =T34*0.8 -> 175.04
A35: DG274G | B35: 194 | C35: =B35*0.8 -> 155.2 | D35: 194 | E35: =D35*0.8 -> 155.2 | F35: 194 | G35: =F35*0.8 -> 155.2 | H35: - | I35: - | J35: - | K35: - | L35: 212.5 | M35: =L35*0.8 -> 170 | N35: 218.5 | O35: =N35*0.8 -> 174.8 | P35: 234 | Q35: =P35*0.8 -> 187.2 | R35: 234 | S35: =R35*0.8 -> 187.2 | T35: 253.3 | U35: =T35*0.8 -> 202.64
A36: DG274H | B36: 220 | C36: =B36*0.8 -> 176 | D36: 220 | E36: =D36*0.8 -> 176 | F36: 220 | G36: =F36*0.8 -> 176 | H36: - | I36: - | J36: - | K36: - | L36: 256.3 | M36: =L36*0.8 -> 205.04 | N36: 256.3 | O36: =N36*0.8 -> 205.04 | P36: 265 | Q36: =P36*0.8 -> 212 | R36: 265 | S36: =R36*0.8 -> 212 | T36: 280 | U36: =T36*0.8 -> 224
A37: DG274J | B37: 260 | C37: =B37*0.8 -> 208 | D37: 260 | E37: =D37*0.8 -> 208 | F37: 260 | G37: =F37*0.8 -> 208 | H37: - | I37: - | J37: - | K37: - | L37: - | M37: - | N37: 294 | O37: =N37*0.8 -> 235.2 | P37: 306 | Q37: =P37*0.8 -> 244.8 | R37: 319 | S37: =R37*0.8 -> 255.2 | T37: 325 | U37: =T37*0.8 -> 260
A38: DG274K | B38: 275 | C38: =B38*0.8 -> 220 | D38: 275 | E38: =D38*0.8 -> 220 | F38: 275 | G38: =F38*0.8 -> 220 | H38: - | I38: - | J38: - | K38: - | L38: 325 | M38: =L38*0.8 -> 260 | N38: 312 | O38: =N38*0.8 -> 249.6 | P38: 320 | Q38: =P38*0.8 -> 256 | R38: 343.8 | S38: =R38*0.8 -> 275.04 | T38: 343.8 | U38: =T38*0.8 -> 275.04
A40: DG444C | B40: 268 | C40: =B40*0.8 -> 214.4 | D40: 268 | E40: =D40*0.8 -> 214.4 | F40: 268 | G40: =F40*0.8 -> 214.4 | H40: 268 | I40: =H40*0.8 -> 214.4 | J40: 331 | K40: =J40*0.8 -> 264.8 | L40: 331 | M40: =L40*0.8 -> 264.8 | N40: 313 | O40: =N40*0.8 -> 250.4 | P40: 325 | Q40: =P40*0.8 -> 260 | R40: 331 | S40: =R40*0.8 -> 264.8 | T40: 344 | U40: =T40*0.8 -> 275.2
A41: DG444D | B41: 324 | C41: =B41*0.8 -> 259.2 | D41: 324 | E41: =D41*0.8 -> 259.2 | F41: 324 | G41: =F41*0.8 -> 259.2 | H41: 305 | I41: =H41*0.8 -> 244 | J41: 383 | K41: =J41*0.8 -> 306.4 | L41: 383 | M41: =L41*0.8 -> 306.4 | N41: 363 | O41: =N41*0.8 -> 290.4 | P41: 383 | Q41: =P41*0.8 -> 306.4 | R41: 398 | S41: =R41*0.8 -> 318.4 | T41: 413 | U41: =T41*0.8 -> 330.4
A42: DGK444D | B42: 330 | C42: =B42*0.8 -> 264 | D42: 330 | E42: =D42*0.8 -> 264 | F42: 330 | G42: =F42*0.8 -> 264 | H42: 320 | I42: =H42*0.8 -> 256 | J42: 383 | K42: =J42*0.8 -> 306.4 | L42: 383 | M42: =L42*0.8 -> 306.4 | N42: 374 | O42: =N42*0.8 -> 299.2 | P42: 396 | Q42: =P42*0.8 -> 316.8 | R42: 413 | S42: =R42*0.8 -> 330.4 | T42: 413 | U42: =T42*0.8 -> 330.4
A43: DG444E | B43: 358 | C43: =B43*0.8 -> 286.4 | D43: 358 | E43: =D43*0.8 -> 286.4 | F43: 358 | G43: =F43*0.8 -> 286.4 | H43: 358 | I43: =H43*0.8 -> 286.4 | J43: - | K43: - | L43: - | M43: - | N43: 419 | O43: =N43*0.8 -> 335.2 | P43: 431 | Q43: =P43*0.8 -> 344.8 | R43: 444 | S43: =R43*0.8 -> 355.2 | T43: 456 | U43: =T43*0.8 -> 364.8
A44: DGK444E | B44: 380 | C44: =B44*0.8 -> 304 | D44: 380 | E44: =D44*0.8 -> 304 | F44: 380 | G44: =F44*0.8 -> 304 | H44: 380 | I44: =H44*0.8 -> 304 | J44: - | K44: - | L44: - | M44: - | N44: 432 | O44: =N44*0.8 -> 345.6 | P44: 456 | Q44: =P44*0.8 -> 364.8 | R44: 475 | S44: =R44*0.8 -> 380 | T44: 475 | U44: =T44*0.8 -> 380
...

Sheet 4P 3PH 150K
A1: Dingol Generator Rating Table (4-pole 3-phase rating)
A2: Model | B2: Three Phase 50Hz 1500RPM | J2: Three Phase 60Hz 1800RPM
A3: Power Factor | B3: 0.8 | D3: 0.8 | F3: 0.8 | H3: 0.8 | J3: 0.8 | L3: 0.8 | N3: 0.8 | P3: 0.8 | R3: 0.8 | T3: 0.8
A4: Volts
A5: Star(W12&W13) | B5: 380 | D5: 400 | F5: 415 | H5: 440 | J5: 380-416 | N5: 416 | P5: 440 | R5: 460 | T5: 480
A6: Delta(W12&W13) | B6: 220 | D6: 230 | F6: 240 | H6: 254 | J6: 220-240 | N6: 240 | P6: 254 | R6: 266 | T6: 277
A7: Series Star(W11&W14) | B7: 380 | D7: 400 | F7: 415 | H7: 440 | J7: - | L7: 380-416 | N7: 416 | P7: 440 | R7: 460 | T7: 480
A8: Parallel Star(W11&W14) | B8: 190 | D8: 200 | F8: 208 | H8: 220 | J8: - | L8: 190-208 | N8: 208 | P8: 220 | R8: 230 | T8: 240
A9: Series Delta | B9: 220 | D9: 230 | F9: 240 | H9: 254 | J9: - | L9: 220-240 | N9: 240 | P9: 254 | R9: 266 | T9: 277
A10: Parallel delta | B10: =B9/2 -> 110 | D10: =D9/2 -> 115 | F10: =F9/2 -> 120 | H10: =H9/2 -> 127 | L10: 110-120 | N10: =N9/2 -> 120 | P10: =P9/2 -> 127 | R10: =R9/2 -> 133 | T10: =T9/2 -> 138.5
A11: Winding No. | B11: 11 | D11: 11 | F11: 11 | H11: 11 | J11: 13 | L11: 14 | N11: 11 | P11: 11 | R11: 11 | T11: 11
A12: Rating | B12: KVA | C12: KW | D12: KVA | E12: KW | F12: KVA | G12: KW | H12: KVA | I12: KW | J12: KVA | K12: KW | L12: KVA | M12: KW | N12: KVA | O12: KW | P12: KVA | Q12: KW | R12: KVA | S12: KW | T12: KVA | U12: KW
A13: DG164A | B13: - | C13: - | D13: - | E13: - | F13: - | G13: - | H13: - | I13: - | L13: - | M13: - | N13: - | O13: - | P13: - | Q13: - | R13: - | S13: - | T13: - | U13: -
A14: DG164B | B14: - | C14: - | D14: - | E14: - | F14: - | G14: - | H14: - | I14: - | L14: - | M14: - | N14: - | O14: - | P14: - | Q14: - | R14: - | S14: - | T14: - | U14: -
A15: DG164C | B15: - | C15: - | D15: - | E15: - | F15: - | G15: - | H15: - | I15: - | L15: - | M15: - | N15: - | O15: - | P15: - | Q15: - | R15: - | S15: - | T15: - | U15: -
A16: DG164D | B16: - | C16: - | D16: - | E16: - | F16: - | G16: - | H16: - | I16: - | L16: - | M16: - | N16: - | O16: - | P16: - | Q16: - | R16: - | S16: - | T16: - | U16: -
A18: DG184ES | B18: - | C18: - | D18: - | E18: - | F18: - | G18: - | H18: - | I18: - | L18: - | M18: - | N18: - | O18: - | P18: - | Q18: - | R18: - | S18: - | T18: - | U18: -
A19: DG184E | B19: - | C19: - | D19: - | E19: - | F19: - | G19: - | H19: - | I19: - | L19: - | M19: - | N19: - | O19: - | P19: - | Q19: - | R19: - | S19: - | T19: - | U19: -
A20: DG184F | B20: 29 | C20: =B20*0.8 -> 23.2 | D20: 29 | E20: =D20*0.8 -> 23.2 | F20: 29 | G20: =F20*0.8 -> 23.2 | H20: 23.7 | I20: =H20*0.8 -> 18.96 | L20: ='4P 3PH rating '!L20*1.03 -> 33.475 | M20: =L20*0.8 -> 26.78 | N20: 33.8 | O20: =N20*0.8 -> 27.04 | P20: 35 | Q20: =P20*0.8 -> 28 | R20: 35 | S20: =R20*0.8 -> 28 | T20: 37.5 | U20: =T20*0.8 -> 30
A21: DG184G | B21: 32.5 | C21: =B21*0.8 -> 26 | D21: 32.5 | E21: =D21*0.8 -> 26 | F21: 32.5 | G21: =F21*0.8 -> 26 | H21: 28.6 | I21: =H21*0.8 -> 22.88 | L21: ='4P 3PH rating '!L21*1.03 -> 38.625 | M21: =L21*0.8 -> 30.9 | N21: 36.3 | O21: =N21*0.8 -> 29.04 | P21: 38.8 | Q21: =P21*0.8 -> 31.04 | R21: 38.8 | S21: =R21*0.8 -> 31.04 | T21: 38.8 | U21: =T21*0.8 -> 31.04
A22: DG184H | B22: 39 | C22: =B22*0.8 -> 31.2 | D22: 39 | E22: =D22*0.8 -> 31.2 | F22: 39 | G22: =F22*0.8 -> 31.2 | H22: 33.8 | I22: =H22*0.8 -> 27.04 | L22: ='4P 3PH rating '!L22*1.03 -> 44.805 | M22: =L22*0.8 -> 35.844 | N22: 45.9 | O22: =N22*0.8 -> 36.72 | P22: 48.5 | Q22: =P22*0.8 -> 38.8 | R22: 48.5 | S22: =R22*0.8 -> 38.8 | T22: 48.5 | U22: =T22*0.8 -> 38.8
A23: DG184J | B23: 41.5 | C23: =B23*0.8 -> 33.2 | D23: 44 | E23: =D23*0.8 -> 35.2 | F23: 41.5 | G23: =F23*0.8 -> 33.2 | H23: 36.3 | I23: =H23*0.8 -> 29.04 | L23: ='4P 3PH rating '!L23*1.03 -> 48.925 | M23: =L23*0.8 -> 39.14 | N23: 49.2 | O23: =N23*0.8 -> 39.36 | P23: 52 | Q23: =P23*0.8 -> 41.6 | R23: 52 | S23: =R23*0.8 -> 41.6 | T23: 52 | U23: =T23*0.8 -> 41.6
A25: DG224C | B25: 45 | C25: =B25*0.8 -> 36 | D25: 45 | E25: =D25*0.8 -> 36 | F25: 45 | G25: =F25*0.8 -> 36 | H25: 31.7 | I25: =H25*0.8 -> 25.36 | L25: 58.1 | M25: =L25*0.8 -> 46.48 | N25: 53.1 | O25: =N25*0.8 -> 42.48 | P25: 55 | Q25: =P25*0.8 -> 44 | R25: 55 | S25: =R25*0.8 -> 44 | T25: 58.1 | U25: =T25*0.8 -> 46.48
A26: DG224D | B26: 53 | C26: =B26*0.8 -> 42.4 | D26: 53 | E26: =D26*0.8 -> 42.4 | F26: 53 | G26: =F26*0.8 -> 42.4 | H26: 39.1 | I26: =H26*0.8 -> 31.28 | L26: 65 | M26: =L26*0.8 -> 52 | N26: 62.5 | O26: =N26*0.8 -> 50 | P26: 65 | Q26: =P26*0.8 -> 52 | R26: 65 | S26: =R26*0.8 -> 52 | T26: 68.8 | U26: =T26*0.8 -> 55.04
A27: DG224E | B27: 61 | C27: =B27*0.8 -> 48.8 | D27: 61 | E27: =D27*0.8 -> 48.8 | F27: 61 | G27: =F27*0.8 -> 48.8 | H27: 45.8 | I27: =H27*0.8 -> 36.64 | L27: 73.8 | M27: =L27*0.8 -> 59.04 | N27: 70 | O27: =N27*0.8 -> 56 | P27: 73.8 | Q27: =P27*0.8 -> 59.04 | R27: 73.8 | S27: =R27*0.8 -> 59.04 | T27: 78.8 | U27: =T27*0.8 -> 63.04
A28: DG224F | B28: 77 | C28: =B28*0.8 -> 61.6 | D28: 77 | E28: =D28*0.8 -> 61.6 | F28: 77 | G28: =F28*0.8 -> 61.6 | H28: 58 | I28: =H28*0.8 -> 46.4 | L28: 89.4 | M28: =L28*0.8 -> 71.52 | N28: 88.8 | O28: =N28*0.8 -> 71.04 | P28: 92.5 | Q28: =P28*0.8 -> 74 | R28: 92.5 | S28: =R28*0.8 -> 74 | T28: 98.8 | U28: =T28*0.8 -> 79.04
A29: DG224G | B29: 87.5 | C29: =B29*0.8 -> 70 | D29: 87.5 | E29: =D29*0.8 -> 70 | F29: 87.5 | G29: =F29*0.8 -> 70 | H29: 76.9 | I29: =H29*0.8 -> 61.52 | L29: 102.5 | M29: =L29*0.8 -> 82 | N29: 98.1 | O29: =N29*0.8 -> 78.48 | P29: 102.5 | Q29: =P29*0.8 -> 82 | R29: 102.5 | S29: =R29*0.8 -> 82 | T29: 110 | U29: =T29*0.8 -> 88
A31: DG274C | B31: 106 | C31: =B31*0.8 -> 84.8 | D31: 106 | E31: =D31*0.8 -> 84.8 | F31: 106 | G31: =F31*0.8 -> 84.8 | H31: - | I31: - | L31: 127 | M31: =L31*0.8 -> 101.6 | N31: 116.3 | O31: =N31*0.8 -> 93.04 | P31: 125 | Q31: =P31*0.8 -> 100 | R31: 125 | S31: =R31*0.8 -> 100 | T31: 132.5 | U31: =T31*0.8 -> 106
A32: DG274D | B32: =C32/0.8 -> 130 | C32: 104 | D32: =E32/0.8 -> 130 | E32: 104 | F32: =G32/0.8 -> 130 | G32: 104 | H32: - | I32: - | L32: 145 | M32: =L32*0.8 -> 116 | N32: 145 | O32: =N32*0.8 -> 116 | P32: 155 | Q32: =P32*0.8 -> 124 | R32: 155 | S32: =R32*0.8 -> 124 | T32: 160 | U32: =T32*0.8 -> 128
A33: DG274E | B33: 145 | C33: =B33*0.8 -> 116 | D33: 145 | E33: =D33*0.8 -> 116 | F33: 145 | G33: =F33*0.8 -> 116 | H33: - | I33: - | L33: 170 | M33: =L33*0.8 -> 136 | N33: 170 | O33: =N33*0.8 -> 136 | P33: 175 | Q33: =P33*0.8 -> 140 | R33: 175 | S33: =R33*0.8 -> 140 | T33: 187.5 | U33: =T33*0.8 -> 150
A34: DG274EL | B34: ='4P 3PH rating '!B34*1.03 -> 154.5 | C34: =B34*0.8 -> 123.6 | D34: ='4P 3PH rating '!D34*1.03 -> 154.5 | E34: =D34*0.8 -> 123.6 | F34: ='4P 3PH rating '!F34*1.03 -> 154.5 | G34: =F34*0.8 -> 123.6 | H34: - | I34: - | L34: ='4P 3PH rating '!L34*1.03 -> 175.1 | M34: =L34*0.8 -> 140.08 | N34: ='4P 3PH rating '!N34*1.03 -> 175.1 | O34: =N34*0.8 -> 140.08 | P34: ='4P 3PH rating '!P34*1.03 -> 185.4 | Q34: =P34*0.8 -> 148.32 | R34: ='4P 3PH rating '!R34*1.03 -> 185.4 | S34: =R34*0.8 -> 148.32 | T34: ='4P 3PH rating '!T34*1.03 -> 195.7 | U34: =T34*0.8 -> 156.56
A35: DG274F | B35: 170 | C35: =B35*0.8 -> 136 | D35: 170 | E35: =D35*0.8 -> 136 | F35: 170 | G35: =F35*0.8 -> 136 | H35: - | I35: - | L35: 186 | M35: =L35*0.8 -> 148.8 | N35: 187.5 | O35: =N35*0.8 -> 150 | P35: 200 | Q35: =P35*0.8 -> 160 | R35: 200 | S35: =R35*0.8 -> 160 | T35: 212.5 | U35: =T35*0.8 -> 170
A36: DG274G | B36: 187 | C36: =B36*0.8 -> 149.6 | D36: 187 | E36: =D36*0.8 -> 149.6 | F36: 187 | G36: =F36*0.8 -> 149.6 | H36: - | I36: - | L36: 207.5 | M36: =L36*0.8 -> 166 | N36: 213 | O36: =N36*0.8 -> 170.4 | P36: 228.8 | Q36: =P36*0.8 -> 183.04 | R36: 228.8 | S36: =R36*0.8 -> 183.04 | T36: 246.8 | U36: =T36*0.8 -> 197.44
A37: DG274H | B37: 212 | C37: =B37*0.8 -> 169.6 | D37: 212 | E37: =D37*0.8 -> 169.6 | F37: 212 | G37: =F37*0.8 -> 169.6 | H37: - | I37: - | L37: 250 | M37: =L37*0.8 -> 200 | N37: 250 | O37: =N37*0.8 -> 200 | P37: 258.8 | Q37: =P37*0.8 -> 207.04 | R37: 258.8 | S37: =R37*0.8 -> 207.04 | T37: 275 | U37: =T37*0.8 -> 220
A38: DG274J | B38: 250 | C38: =B38*0.8 -> 200 | D38: 250 | E38: =D38*0.8 -> 200 | F38: 250 | G38: =F38*0.8 -> 200 | H38: - | I38: - | L38: 292 | M38: =L38*0.8 -> 233.6 | N38: 288 | O38: =N38*0.8 -> 230.4 | P38: 300 | Q38: =P38*0.8 -> 240 | R38: 313 | S38: =R38*0.8 -> 250.4 | T38: 319 | U38: =T38*0.8 -> 255.2
A39: DG274K | B39: 265 | C39: =B39*0.8 -> 212 | D39: 265 | E39: =D39*0.8 -> 212 | F39: 265 | G39: =F39*0.8 -> 212 | H39: - | I39: - | L39: 319 | M39: =L39*0.8 -> 255.2 | N39: 304 | O39: =N39*0.8 -> 243.2 | P39: 312.5 | Q39: =P39*0.8 -> 250 | R39: 331.3 | S39: =R39*0.8 -> 265.04 | T39: 331.3 | U39: =T39*0.8 -> 265.04
A41: DG444C | B41: 259 | C41: =B41*0.8 -> 207.2 | D41: 259 | E41: =D41*0.8 -> 207.2 | F41: 259 | G41: =F41*0.8 -> 207.2 | H41: 259 | I41: =H41*0.8 -> 207.2 | J41: 319 | K41: =J41*0.8 -> 255.2 | L41: 319 | M41: =L41*0.8 -> 255.2 | N41: 300 | O41: =N41*0.8 -> 240 | P41: 313 | Q41: =P41*0.8 -> 250.4 | R41: 319 | S41: =R41*0.8 -> 255.2 | T41: 332 | U41: =T41*0.8 -> 265.6
A42: DG444D | B42: 313 | C42: =B42*0.8 -> 250.4 | D42: 313 | E42: =D42*0.8 -> 250.4 | F42: 313 | G42: =F42*0.8 -> 250.4 | H42: 295 | I42: =H42*0.8 -> 236 | J42: 375 | K42: =J42*0.8 -> 300 | L42: 375 | M42: =L42*0.8 -> 300 | N42: 356 | O42: =N42*0.8 -> 284.8 | P42: 375 | Q42: =P42*0.8 -> 300 | R42: 388 | S42: =R42*0.8 -> 310.4 | T42: 400 | U42: =T42*0.8 -> 320
A43: DGK444D | B43: 320 | C43: =B43*0.8 -> 256 | D43: 320 | E43: =D43*0.8 -> 256 | F43: 320 | G43: =F43*0.8 -> 256 | H43: 310 | I43: =H43*0.8 -> 248 | J43: 380 | K43: =J43*0.8 -> 304 | L43: 380 | M43: =L43*0.8 -> 304 | N43: 363 | O43: =N43*0.8 -> 290.4 | P43: 384 | Q43: =P43*0.8 -> 307.2 | R43: 400 | S43: =R43*0.8 -> 320 | T43: 400 | U43: =T43*0.8 -> 320
A44: DG444E | B44: 345 | C44: =B44*0.8 -> 276 | D44: 345 | E44: =D44*0.8 -> 276 | F44: 345 | G44: =F44*0.8 -> 276 | H44: 345 | I44: =H44*0.8 -> 276 | J44: - | K44: - | L44: - | M44: - | N44: 406 | O44: =N44*0.8 -> 324.8 | P44: 419 | Q44: =P44*0.8 -> 335.2 | R44: 431 | S44: =R44*0.8 -> 344.8 | T44: 444 | U44: =T44*0.8 -> 355.2
...

Sheet 4P 3PH 163K
A1: Dingol Generator Rating Table (4-pole 3-phase rating)
A2: Model | B2: Three Phase 50Hz 1500RPM | J2: Three Phase 60Hz 1800RPM
A3: Power Factor | B3: 0.8 | D3: 0.8 | F3: 0.8 | H3: 0.8 | J3: 0.8 | L3: 0.8 | N3: 0.8 | P3: 0.8 | R3: 0.8 | T3: 0.8
A4: Volts
A5: Star(W12&W13) | B5: 380 | D5: 400 | F5: 415 | H5: 440 | J5: 380-416 | N5: 416 | P5: 440 | R5: 460 | T5: 480
A6: Delta(W12&W13) | B6: 220 | D6: 230 | F6: 240 | H6: 254 | J6: 220-240 | N6: 240 | P6: 254 | R6: 266 | T6: 277
A7: Series Star(W11&W14) | B7: 380 | D7: 400 | F7: 415 | H7: 440 | J7: - | L7: 380-416 | N7: 416 | P7: 440 | R7: 460 | T7: 480
A8: Parallel Star(W11&W14) | B8: 190 | D8: 200 | F8: 208 | H8: 220 | J8: - | L8: 190-208 | N8: 208 | P8: 220 | R8: 230 | T8: 240
A9: Series Delta | B9: 220 | D9: 230 | F9: 240 | H9: 254 | J9: - | L9: 220-240 | N9: 240 | P9: 254 | R9: 266 | T9: 277
A10: Parallel delta | B10: =B9/2 -> 110 | D10: =D9/2 -> 115 | F10: =F9/2 -> 120 | H10: =H9/2 -> 127 | L10: 110-120 | N10: =N9/2 -> 120 | P10: =P9/2 -> 127 | R10: =R9/2 -> 133 | T10: =T9/2 -> 138.5
A11: Winding No. | B11: 11 | D11: 11 | F11: 11 | H11: 11 | J11: 13 | L11: 14 | N11: 11 | P11: 11 | R11: 11 | T11: 11
A12: Rating | B12: KVA | C12: KW | D12: KVA | E12: KW | F12: KVA | G12: KW | H12: KVA | I12: KW | J12: KVA | K12: KW | L12: KVA | M12: KW | N12: KVA | O12: KW | P12: KVA | Q12: KW | R12: KVA | S12: KW | T12: KVA | U12: KW
A13: DG164A | B13: - | C13: - | D13: - | E13: - | F13: - | G13: - | H13: - | I13: - | L13: - | M13: - | N13: - | O13: - | P13: - | Q13: - | R13: - | S13: - | T13: - | U13: -
A14: DG164B | B14: - | C14: - | D14: - | E14: - | F14: - | G14: - | H14: - | I14: - | L14: - | M14: - | N14: - | O14: - | P14: - | Q14: - | R14: - | S14: - | T14: - | U14: -
A15: DG164C | B15: - | C15: - | D15: - | E15: - | F15: - | G15: - | H15: - | I15: - | L15: - | M15: - | N15: - | O15: - | P15: - | Q15: - | R15: - | S15: - | T15: - | U15: -
A16: DG164D | B16: - | C16: - | D16: - | E16: - | F16: - | G16: - | H16: - | I16: - | L16: - | M16: - | N16: - | O16: - | P16: - | Q16: - | R16: - | S16: - | T16: - | U16: -
A18: DG184ES | B18: - | C18: - | D18: - | E18: - | F18: - | G18: - | H18: - | I18: - | L18: - | M18: - | N18: - | O18: - | P18: - | Q18: - | R18: - | S18: - | T18: - | U18: -
A19: DG184E | B19: - | C19: - | D19: - | E19: - | F19: - | G19: - | H19: - | I19: - | L19: - | M19: - | N19: - | O19: - | P19: - | Q19: - | R19: - | S19: - | T19: - | U19: -
A20: DG184F | B20: 30 | C20: =B20*0.8 -> 24 | D20: 30 | E20: =D20*0.8 -> 24 | F20: 30 | G20: =F20*0.8 -> 24 | H20: 24.5 | I20: =H20*0.8 -> 19.6 | J20: - | K20: - | L20: ='4P 3PH rating '!L20*1.05 -> 34.125 | M20: ='4P 3PH rating '!M20*1.05 -> 27.3 | N20: 34.4 | O20: =N20*0.8 -> 27.52 | P20: 35.6 | Q20: =P20*0.8 -> 28.48 | R20: 35.6 | S20: =Q20*0.8 -> 22.784 | T20: 38.8 | U20: =T20*0.8 -> 31.04
A21: DG184G | B21: 33 | C21: =B21*0.8 -> 26.4 | D21: 33 | E21: =D21*0.8 -> 26.4 | F21: 33 | G21: =F21*0.8 -> 26.4 | H21: 29 | I21: =H21*0.8 -> 23.2 | J21: - | K21: - | L21: ='4P 3PH rating '!L21*1.05 -> 39.375 | M21: ='4P 3PH rating '!M21*1.05 -> 31.5 | N21: 36.9 | O21: =N21*0.8 -> 29.52 | P21: 40 | Q21: =P21*0.8 -> 32 | R21: 40 | S21: =Q21*0.8 -> 25.6 | T21: 40 | U21: =T21*0.8 -> 32
A22: DG184H | B22: 40 | C22: =B22*0.8 -> 32 | D22: 40 | E22: =D22*0.8 -> 32 | F22: 40 | G22: =F22*0.8 -> 32 | H22: 34.7 | I22: =H22*0.8 -> 27.76 | J22: - | K22: - | L22: ='4P 3PH rating '!L22*1.05 -> 45.675 | M22: ='4P 3PH rating '!M22*1.05 -> 36.54 | N22: 47.3 | O22: =N22*0.8 -> 37.84 | P22: 50 | Q22: =P22*0.8 -> 40 | R22: 50 | S22: =Q22*0.8 -> 32 | T22: 50 | U22: =T22*0.8 -> 40
A23: DG184J | B23: 42.5 | C23: =B23*0.8 -> 34 | D23: 45 | E23: =D23*0.8 -> 36 | F23: 42.5 | G23: =F23*0.8 -> 34 | H23: 37.2 | I23: =H23*0.8 -> 29.76 | J23: - | K23: - | L23: ='4P 3PH rating '!L23*1.05 -> 49.875 | M23: ='4P 3PH rating '!M23*1.05 -> 39.9 | N23: 50.6 | O23: =N23*0.8 -> 40.48 | P23: 53.5 | Q23: =P23*0.8 -> 42.8 | R23: 53.5 | S23: =Q23*0.8 -> 34.24 | T23: 53.5 | U23: =T23*0.8 -> 42.8
A25: DG224C | B25: 46.8 | C25: =B25*0.8 -> 37.44 | D25: 46.8 | E25: =D25*0.8 -> 37.44 | F25: 46.8 | G25: =F25*0.8 -> 37.44 | H25: 33 | I25: =H25*0.8 -> 26.4 | J25: - | K25: - | L25: 60 | M25: =L25*0.8 -> 48 | N25: 55 | O25: =N25*0.8 -> 44 | P25: 56.3 | Q25: =P25*0.8 -> 45.04 | R25: 56.3 | S25: =R25*0.8 -> 45.04 | T25: 60 | U25: =T25*0.8 -> 48
A26: DG224D | B26: 55 | C26: =B26*0.8 -> 44 | D26: 55 | E26: =D26*0.8 -> 44 | F26: 55 | G26: =F26*0.8 -> 44 | H26: 41.2 | I26: =H26*0.8 -> 32.96 | J26: - | K26: - | L26: 66.3 | M26: =L26*0.8 -> 53.04 | N26: 65 | O26: =N26*0.8 -> 52 | P26: 66.3 | Q26: =P26*0.8 -> 53.04 | R26: 66.3 | S26: =R26*0.8 -> 53.04 | T26: 71.3 | U26: =T26*0.8 -> 57.04
A27: DG224E | B27: 63 | C27: =B27*0.8 -> 50.4 | D27: 63 | E27: =D27*0.8 -> 50.4 | F27: 63 | G27: =F27*0.8 -> 50.4 | H27: 47.3 | I27: =H27*0.8 -> 37.84 | J27: - | K27: - | L27: 75 | M27: =L27*0.8 -> 60 | N27: 72.5 | O27: =N27*0.8 -> 58 | P27: 75 | Q27: =P27*0.8 -> 60 | R27: 75 | S27: =R27*0.8 -> 60 | T27: 80 | U27: =T27*0.8 -> 64
A28: DG224F | B28: 80 | C28: =B28*0.8 -> 64 | D28: 80 | E28: =D28*0.8 -> 64 | F28: 80 | G28: =F28*0.8 -> 64 | H28: 60.4 | I28: =H28*0.8 -> 48.32 | J28: - | K28: - | L28: 92 | M28: =L28*0.8 -> 73.6 | N28: 91.9 | O28: =N28*0.8 -> 73.52 | P28: 95 | Q28: =P28*0.8 -> 76 | R28: 95 | S28: =R28*0.8 -> 76 | T28: 102.5 | U28: =T28*0.8 -> 82
A29: DG224G | B29: 90.8 | C29: =B29*0.8 -> 72.64 | D29: 90.8 | E29: =D29*0.8 -> 72.64 | F29: 90.8 | G29: =F29*0.8 -> 72.64 | H29: 80.1 | I29: =H29*0.8 -> 64.08 | J29: - | K29: - | L29: 106.3 | M29: =L29*0.8 -> 85.04 | N29: 101.3 | O29: =N29*0.8 -> 81.04 | P29: 106.3 | Q29: =P29*0.8 -> 85.04 | R29: 106.3 | S29: =R29*0.8 -> 85.04 | T29: 113.8 | U29: =T29*0.8 -> 91.04
A31: DG274C | B31: 110 | C31: =B31*0.8 -> 88 | D31: 110 | E31: =D31*0.8 -> 88 | F31: 110 | G31: =F31*0.8 -> 88 | H31: - | I31: - | J31: - | K31: - | L31: 132 | M31: =L31*0.8 -> 105.6 | N31: 120 | O31: =N31*0.8 -> 96 | P31: 127.5 | Q31: =P31*0.8 -> 102 | R31: 127.5 | S31: =R31*0.8 -> 102 | T31: 137.5 | U31: =T31*0.8 -> 110
A32: DG274D | B32: =C32/0.8 -> 132.5 | C32: 106 | D32: =E32/0.8 -> 132.5 | E32: 106 | F32: =G32/0.8 -> 132.5 | G32: 106 | H32: - | I32: - | J32: - | K32: - | L32: 150 | M32: =L32*0.8 -> 120 | N32: 150 | O32: =N32*0.8 -> 120 | P32: 160 | Q32: =P32*0.8 -> 128 | R32: 160 | S32: =R32*0.8 -> 128 | T32: 160 | U32: =T32*0.8 -> 128
A33: DG274E | B33: 150 | C33: =B33*0.8 -> 120 | D33: 150 | E33: =D33*0.8 -> 120 | F33: 150 | G33: =F33*0.8 -> 120 | H33: - | I33: - | J33: - | K33: - | L33: 175 | M33: =L33*0.8 -> 140 | N33: 175 | O33: =N33*0.8 -> 140 | P33: 181.3 | Q33: =P33*0.8 -> 145.04 | R33: 181.3 | S33: =R33*0.8 -> 145.04 | T33: 193.8 | U33: =T33*0.8 -> 155.04
